Workbook

Sheet pivot
A3: Month | B3: Sum of Revenue | J3: Month | K3: Sum of Expenses
A4: Jan | B4: 120000 | J4: Jan | K4: 95000
A5: Feb | B5: 135000 | J5: Feb | K5: 98000
A6: Mar | B6: 150000 | J6: Mar | K6: 105000
A7: Apr | B7: 165000 | J7: Apr | K7: 112000
A8: May | B8: 182000 | J8: May | K8: 120000
A9: Jun | B9: 198000 | J9: Jun | K9: 130000
A10: Jul | B10: 215000 | J10: Jul | K10: 138000
A11: Aug | B11: 232000 | J11: Aug | K11: 145000
A12: Sep | B12: 248000 | J12: Sep | K12: 153000
A13: Oct | B13: 265000 | J13: Oct | K13: 162000
A14: Nov | B14: 285000 | J14: Nov | K14: 170000
A15: Dec | B15: 310000 | J15: Dec | K15: 182000
A16: Grand Total | B16: 2505000 | J16: Grand Total | K16: 1610000
A18: Month | B18: Sum of Profit | J18: Month | K18: Sum of Active_Customers
A19: Jan | B19: 25000 | J19: Jan | K19: 500
A20: Feb | B20: 37000 | J20: Feb | K20: 615
A21: Mar | B21: 45000 | J21: Mar | K21: 742
A22: Apr | B22: 53000 | J22: Apr | K22: 880
A23: May | B23: 62000 | J23: May | K23: 1030
A24: Jun | B24: 68000 | J24: Jun | K24: 1187
A25: Jul | B25: 77000 | J25: Jul | K25: 1352
A26: Aug | B26: 87000 | J26: Aug | K26: 1523
A27: Sep | B27: 95000 | J27: Sep | K27: 1702
A28: Oct | B28: 103000 | J28: Oct | K28: 1889
A29: Nov | B29: 115000 | J29: Nov | K29: 2082
A30: Dec | B30: 128000 | J30: Dec | K30: 2287
A31: Grand Total | B31: 895000 | J31: Grand Total | K31: 15789
C33: Month | D33: Sum of LTV | E33: Sum of CAC
C34: Jan | D34: 1920 | E34: 125
C35: Feb | D35: 1756.0976 | E35: 118.51852
C36: Mar | D36: 1584.9057 | E36: 124.13793
C37: Apr | D37: 1472.7273 | E37: 118.75
C38: May | D38: 1398.0583 | E38: 120
C39: Jun | D39: 1334.4566 | E39: 118.91892
C40: Jul | D40: 1286.9822 | E40: 123.07692
C41: Aug | D41: 1244.9114 | E41: 121.95122
C42: Sep | D42: 1205.6404 | E42: 120.93023
C43: Oct | D43: 1168.8724 | E43: 124.44444
C44: Nov | D44: 1141.2104 | E44: 123.40426
...

Sheet Startup_Financials
A1: Month | B1: Revenue | C1: Expenses | D1: Marketing_Cost | E1: New_Customers | F1: Active_Customers | G1: Churn_Customers | H1: Subscription_Revenue | I1: Operating_Cost | J1: Profit | K1: Profit Margin % | L1: CAC | M1: LTV | N1: LTV:CAC Ratio | O1: Burn Rate
A2: Jan | B2: 120000 | C2: 95000 | D2: 15000 | E2: 120 | F2: 500 | G2: 20 | H2: 80000 | I2: 60000 | J2: =Financial_Data[[#This Row],[Revenue]]-Financial_Data[[#This Row],[Expenses]] -> 25000 | K2: =Financial_Data[[#This Row],[Profit]]/Financial_Data[[#This Row],[Revenue]]*100 -> 20.833333 | L2: =Financial_Data[[#This Row],[Marketing_Cost]]/Financial_Data[[#This Row],[New_Customers]] -> 125 | M2: =(Financial_Data[[#This Row],[Subscription_Revenue]]/Financial_Data[[#This Row],[Active_Customers]])*12 -> 1920 | N2: =Financial_Data[[#This Row],[LTV]]/Financial_Data[[#This Row],[CAC]] -> 15.36 | O2: =ABS(Financial_Data[[#This Row],[Expenses]]-Financial_Data[[#This Row],[Revenue]]) -> 25000
A3: Feb | B3: 135000 | C3: 98000 | D3: 16000 | E3: 135 | F3: 615 | G3: 18 | H3: 90000 | I3: 62000 | J3: =Financial_Data[[#This Row],[Revenue]]-Financial_Data[[#This Row],[Expenses]] -> 37000 | K3: =Financial_Data[[#This Row],[Profit]]/Financial_Data[[#This Row],[Revenue]]*100 -> 27.407407 | L3: =Financial_Data[[#This Row],[Marketing_Cost]]/Financial_Data[[#This Row],[New_Customers]] -> 118.51852 | M3: =(Financial_Data[[#This Row],[Subscription_Revenue]]/Financial_Data[[#This Row],[Active_Customers]])*12 -> 1756.0976 | N3: =Financial_Data[[#This Row],[LTV]]/Financial_Data[[#This Row],[CAC]] -> 14.817073 | O3: =ABS(Financial_Data[[#This Row],[Expenses]]-Financial_Data[[#This Row],[Revenue]]) -> 37000
A4: Mar | B4: 150000 | C4: 105000 | D4: 18000 | E4: 145 | F4: 742 | G4: 22 | H4: 98000 | I4: 65000 | J4: =Financial_Data[[#This Row],[Revenue]]-Financial_Data[[#This Row],[Expenses]] -> 45000 | K4: =Financial_Data[[#This Row],[Profit]]/Financial_Data[[#This Row],[Revenue]]*100 -> 30 | L4: =Financial_Data[[#This Row],[Marketing_Cost]]/Financial_Data[[#This Row],[New_Customers]] -> 124.13793 | M4: =(Financial_Data[[#This Row],[Subscription_Revenue]]/Financial_Data[[#This Row],[Active_Customers]])*12 -> 1584.9057 | N4: =Financial_Data[[#This Row],[LTV]]/Financial_Data[[#This Row],[CAC]] -> 12.767296 | O4: =ABS(Financial_Data[[#This Row],[Expenses]]-Financial_Data[[#This Row],[Revenue]]) -> 45000
A5: Apr | B5: 165000 | C5: 112000 | D5: 19000 | E5: 160 | F5: 880 | G5: 25 | H5: 108000 | I5: 68000 | J5: =Financial_Data[[#This Row],[Revenue]]-Financial_Data[[#This Row],[Expenses]] -> 53000 | K5: =Financial_Data[[#This Row],[Profit]]/Financial_Data[[#This Row],[Revenue]]*100 -> 32.121212 | L5: =Financial_Data[[#This Row],[Marketing_Cost]]/Financial_Data[[#This Row],[New_Customers]] -> 118.75 | M5: =(Financial_Data[[#This Row],[Subscription_Revenue]]/Financial_Data[[#This Row],[Active_Customers]])*12 -> 1472.7273 | N5: =Financial_Data[[#This Row],[LTV]]/Financial_Data[[#This Row],[CAC]] -> 12.401914 | O5: =ABS(Financial_Data[[#This Row],[Expenses]]-Financial_Data[[#This Row],[Revenue]]) -> 53000
A6: May | B6: 182000 | C6: 120000 | D6: 21000 | E6: 175 | F6: 1030 | G6: 28 | H6: 120000 | I6: 71000 | J6: =Financial_Data[[#This Row],[Revenue]]-Financial_Data[[#This Row],[Expenses]] -> 62000 | K6: =Financial_Data[[#This Row],[Profit]]/Financial_Data[[#This Row],[Revenue]]*100 -> 34.065934 | L6: =Financial_Data[[#This Row],[Marketing_Cost]]/Financial_Data[[#This Row],[New_Customers]] -> 120 | M6: =(Financial_Data[[#This Row],[Subscription_Revenue]]/Financial_Data[[#This Row],[Active_Customers]])*12 -> 1398.0583 | N6: =Financial_Data[[#This Row],[LTV]]/Financial_Data[[#This Row],[CAC]] -> 11.650485 | O6: =ABS(Financial_Data[[#This Row],[Expenses]]-Financial_Data[[#This Row],[Revenue]]) -> 62000
A7: Jun | B7: 198000 | C7: 130000 | D7: 22000 | E7: 185 | F7: 1187 | G7: 30 | H7: 132000 | I7: 74000 | J7: =Financial_Data[[#This Row],[Revenue]]-Financial_Data[[#This Row],[Expenses]] -> 68000 | K7: =Financial_Data[[#This Row],[Profit]]/Financial_Data[[#This Row],[Revenue]]*100 -> 34.343434 | L7: =Financial_Data[[#This Row],[Marketing_Cost]]/Financial_Data[[#This Row],[New_Customers]] -> 118.91892 | M7: =(Financial_Data[[#This Row],[Subscription_Revenue]]/Financial_Data[[#This Row],[Active_Customers]])*12 -> 1334.4566 | N7: =Financial_Data[[#This Row],[LTV]]/Financial_Data[[#This Row],[CAC]] -> 11.221567 | O7: =ABS(Financial_Data[[#This Row],[Expenses]]-Financial_Data[[#This Row],[Revenue]]) -> 68000
A8: Jul | B8: 215000 | C8: 138000 | D8: 24000 | E8: 195 | F8: 1352 | G8: 34 | H8: 145000 | I8: 77000 | J8: =Financial_Data[[#This Row],[Revenue]]-Financial_Data[[#This Row],[Expenses]] -> 77000 | K8: =Financial_Data[[#This Row],[Profit]]/Financial_Data[[#This Row],[Revenue]]*100 -> 35.813953 | L8: =Financial_Data[[#This Row],[Marketing_Cost]]/Financial_Data[[#This Row],[New_Customers]] -> 123.07692 | M8: =(Financial_Data[[#This Row],[Subscription_Revenue]]/Financial_Data[[#This Row],[Active_Customers]])*12 -> 1286.9822 | N8: =Financial_Data[[#This Row],[LTV]]/Financial_Data[[#This Row],[CAC]] -> 10.456731 | O8: =ABS(Financial_Data[[#This Row],[Expenses]]-Financial_Data[[#This Row],[Revenue]]) -> 77000
A9: Aug | B9: 232000 | C9: 145000 | D9: 25000 | E9: 205 | F9: 1523 | G9: 36 | H9: 158000 | I9: 80000 | J9: =Financial_Data[[#This Row],[Revenue]]-Financial_Data[[#This Row],[Expenses]] -> 87000 | K9: =Financial_Data[[#This Row],[Profit]]/Financial_Data[[#This Row],[Revenue]]*100 -> 37.5 | L9: =Financial_Data[[#This Row],[Marketing_Cost]]/Financial_Data[[#This Row],[New_Customers]] -> 121.95122 | M9: =(Financial_Data[[#This Row],[Subscription_Revenue]]/Financial_Data[[#This Row],[Active_Customers]])*12 -> 1244.9114 | N9: =Financial_Data[[#This Row],[LTV]]/Financial_Data[[#This Row],[CAC]] -> 10.208273 | O9: =ABS(Financial_Data[[#This Row],[Expenses]]-Financial_Data[[#This Row],[Revenue]]) -> 87000
A10: Sep | B10: 248000 | C10: 153000 | D10: 26000 | E10: 215 | F10: 1702 | G10: 38 | H10: 171000 | I10: 83000 | J10: =Financial_Data[[#This Row],[Revenue]]-Financial_Data[[#This Row],[Expenses]] -> 95000 | K10: =Financial_Data[[#This Row],[Profit]]/Financial_Data[[#This Row],[Revenue]]*100 -> 38.306452 | L10: =Financial_Data[[#This Row],[Marketing_Cost]]/Financial_Data[[#This Row],[New_Customers]] -> 120.93023 | M10: =(Financial_Data[[#This Row],[Subscription_Revenue]]/Financial_Data[[#This Row],[Active_Customers]])*12 -> 1205.6404 | N10: =Financial_Data[[#This Row],[LTV]]/Financial_Data[[#This Row],[CAC]] -> 9.9697189 | O10: =ABS(Financial_Data[[#This Row],[Expenses]]-Financial_Data[[#This Row],[Revenue]]) -> 95000
A11: Oct | B11: 265000 | C11: 162000 | D11: 28000 | E11: 225 | F11: 1889 | G11: 42 | H11: 184000 | I11: 86000 | J11: =Financial_Data[[#This Row],[Revenue]]-Financial_Data[[#This Row],[Expenses]] -> 103000 | K11: =Financial_Data[[#This Row],[Profit]]/Financial_Data[[#This Row],[Revenue]]*100 -> 38.867925 | L11: =Financial_Data[[#This Row],[Marketing_Cost]]/Financial_Data[[#This Row],[New_Customers]] -> 124.44444 | M11: =(Financial_Data[[#This Row],[Subscription_Revenue]]/Financial_Data[[#This Row],[Active_Customers]])*12 -> 1168.8724 | N11: =Financial_Data[[#This Row],[LTV]]/Financial_Data[[#This Row],[CAC]] -> 9.3927248 | O11: =ABS(Financial_Data[[#This Row],[Expenses]]-Financial_Data[[#This Row],[Revenue]]) -> 103000
A12: Nov | B12: 285000 | C12: 170000 | D12: 29000 | E12: 235 | F12: 2082 | G12: 45 | H12: 198000 | I12: 90000 | J12: =Financial_Data[[#This Row],[Revenue]]-Financial_Data[[#This Row],[Expenses]] -> 115000 | K12: =Financial_Data[[#This Row],[Profit]]/Financial_Data[[#This Row],[Revenue]]*100 -> 40.350877 | L12: =Financial_Data[[#This Row],[Marketing_Cost]]/Financial_Data[[#This Row],[New_Customers]] -> 123.40426 | M12: =(Financial_Data[[#This Row],[Subscription_Revenue]]/Financial_Data[[#This Row],[Active_Customers]])*12 -> 1141.2104 | N12: =Financial_Data[[#This Row],[LTV]]/Financial_Data[[#This Row],[CAC]] -> 9.2477392 | O12: =ABS(Financial_Data[[#This Row],[Expenses]]-Financial_Data[[#This Row],[Revenue]]) -> 115000
A13: Dec | B13: 310000 | C13: 182000 | D13: 31000 | E13: 250 | F13: 2287 | G13: 48 | H13: 215000 | I13: 95000 | J13: =Financial_Data[[#This Row],[Revenue]]-Financial_Data[[#This Row],[Expenses]] -> 128000 | K13: =Financial_Data[[#This Row],[Profit]]/Financial_Data[[#This Row],[Revenue]]*100 -> 41.290323 | L13: =Financial_Data[[#This Row],[Marketing_Cost]]/Financial_Data[[#This Row],[New_Customers]] -> 124 | M13: =(Financial_Data[[#This Row],[Subscription_Revenue]]/Financial_Data[[#This Row],[Active_Customers]])*12 -> 1128.1154 | N13: =Financial_Data[[#This Row],[LTV]]/Financial_Data[[#This Row],[CAC]] -> 9.0977051 | O13: =ABS(Financial_Data[[#This Row],[Expenses]]-Financial_Data[[#This Row],[Revenue]]) -> 128000

Sheet KPI_Formulas
A1: Metric | B1: Formula / Value
A2: Total Revenue | B2: =SUM(Startup_Financials!B2:B13) -> 2505000
A3: Total Expenses | B3: =SUM(Startup_Financials!C2:C13) -> 1610000
A4: Net Profit | B4: =B2-B3 -> 895000
A5: Burn Rate (Monthly Avg) | B5: =AVERAGE(Startup_Financials!C2:C13) -> 134166.67
A6: Total Marketing Cost | B6: =SUM(Startup_Financials!D2:D13) -> 274000
A7: Total New Customers | B7: =SUM(Startup_Financials!E2:E13) -> 2245
A8: CAC | B8: =B6/B7 -> 122.049
A9: Average Revenue | B9: =AVERAGE(Startup_Financials!B2:B13) -> 208750
A10: Average Active Customers | B10: =AVERAGE(Startup_Financials!F2:F13) -> 1315.75

Sheet Dashboard
A1: Startup Financial KPI Dashboard
A4: Total Revenue | B4: =KPI_Formulas!B2 -> 2505000 | C4: Total Expensive | D4: =KPI_Formulas!B3 -> 1610000 | E4: Total Profit | F4: =KPI_Formulas!B4 -> 895000 | G4: Average CAC | H4: =KPI_Formulas!B8 -> 122.049 | I4: Average LTV | J4: =AVERAGE(Startup_Financials!M2:M13) -> 1386.8315
